Workbook

Sheet Cover
B2: NVIDIA CORPORATION (NASDAQ: NVDA)
B3: Discounted Cash Flow Valuation — Institutional-Quality Model
B8: Prepared for: | C8: Investment Banking / Equity Research / PE Portfolio Project
B9: Analyst: | C9: Parth Kaushik
B10: Date prepared: | C10: August 2026
B11: Ticker / Exchange: | C11: NVDA / NASDAQ
B12: Sector: | C12: Information Technology — Semiconductors
B13: Fiscal year end: | C13: Late January (FY2026 = year ended 1/25/2026)
B16: MODEL SUMMARY
B17: Active scenario: | C17: =Inputs!C3 -> Base
B18: WACC (active): | C18: =Inputs!F29 -> 0.14425
B19: Current share price: | C19: =Inputs!C6 -> 215
B20: Intrinsic value — Perpetuity method: | C20: =DCF!C20 -> 100.93222
B21: Intrinsic value — Exit multiple method: | C21: =DCF!C31 -> 206.66769
B24: DISCLAIMER
B25: This model is an educational / portfolio project built for training and interview-preparation purposes. It is not investment advice and should not be relied upon to make an actual investment decision. All historical figures are sourced from NVIDIA's SEC filings and public disclosures as cited throughout the workbook; all forecast figures are the analyst's own estimates and assumptions.

Sheet Instructions
B2: HOW TO USE THIS WORKBOOK
B4: Tab | C4: Purpose
B5: Cover | C5: Title page and one-line model summary (pulls live from DCF tab).
B6: Instructions | C6: This tab.
B7: Inputs | C7: EVERY assumption in the model lives here, including the Bear/Base/Bull scenario toggle. Change the dropdown in cell C3 and the entire model — Forecast, WACC, DCF, Dashboard — recalculates automatically.
B8: Historical | C8: FY2022–FY2026 actual income statement, sourced from NVIDIA's 10-K filings and earnings releases.
B9: Forecast | C9: FY2027–FY2031 revenue-to-free-cash-flow build. Every driver (growth, margin, opex, tax, capex, NWC) is pulled from the Inputs tab's Active column.
B10: WACC | C10: Full CAPM-based derivation of the base-case discount rate.
B11: DCF | C11: Discounts the forecast FCF, builds terminal value under BOTH the Perpetuity Growth and Exit Multiple methods, and bridges to an intrinsic share price.
B12: Sensitivity | C12: Two-way data tables: WACC vs. Terminal Growth, and WACC vs. Exit Multiple.
B13: Dashboard | C13: One-page summary of the active scenario's outputs.
B14: Charts | C14: Revenue and free cash flow trend charts.
B16: COLOR LEGEND (WALL STREET STANDARD)
B18: Blue text | C18: Hardcoded input / assumption — safe to edit.
B19: Black text | C19: Formula on the same sheet — do not overwrite.
B20: Green text | C20: Link pulling from a different tab — do not overwrite.
B21: Yellow fill | C21: Key assumption or scenario lever worth double-checking before you rely on the output.
B23: HOW THE SCENARIO TOGGLE WORKS
B25: Inputs!C3 is a data-validation dropdown (Bear / Base / Bull). Every year-by-year driver table on the Inputs tab (revenue growth, gross margin, opex %, tax rate, D&A %, capex %, NWC %) has a Bear, Base, and Bull column plus an 'Active' column that resolves via an IF formula keyed off C3. The Forecast, WACC, and DCF tabs reference ONLY the Active column — so flipping the dropdown reruns the entire five-year model and the DCF output instantly, with no manual re-entry. This mirrors how scenario toggles are actually built in professional models (versus building three separate, hard-to-maintain copies of the same tab).
B31: KNOWN MODEL LIMITATIONS (READ BEFORE PRESENTING)
B33: • | C33: RESOLVED (previously flagged): FY2023 and FY2025 operating income / net income on the Historical tab are now exact figures sourced directly from NVIDIA's GAAP earnings releases, not approximations.
B34: • | C34: The Sensitivity tab's two-way tables flex WACC, terminal growth, and exit multiple around whichever scenario is currently Active on the Inputs tab — they do not hold a fixed 'Base' case regardless of the toggle.
B35: • | C35: RESOLVED (previously flagged): CapEx % of revenue and NWC % of incremental revenue now taper year-by-year within each scenario (5 distinct values per scenario, not a flat rate), consistent with the ramp/maturation logic discussed in the written Part 3 and Part 6 analysis.
B36: • | C36: Discounting uses year-end convention, not mid-year convention — a common refinement in more advanced models.

Sheet Inputs
B1: NVIDIA DCF MODEL — ASSUMPTIONS & SCENARIO INPUTS
B3: ACTIVE SCENARIO (change here): | C3: Base | H3: Every driver table below feeds Forecast/WACC/DCF only through its 'Active' column, which is keyed off this cell.
B5: Market & Capital Structure Inputs (not scenario-dependent)
B6: Current share price ($) | C6: 215 | H6: Approx. trading price, early Aug 2026. Source: stockanalysis.com / market data, 8/7/2026.
B7: Diluted shares outstanding (billions) | C7: 24.22 | H7: Source: NVIDIA FY2026 10-K / stockanalysis.com statistics, Aug 2026.
B8: Cash & short-term investments ($B) | C8: 53.2 | H8: Source: NVIDIA Q1 FY2027 10-Q balance sheet (latest reported quarter).
B9: Total debt ($B) | C9: 38 | H9: Est. incl. new $25B bond issuance, June 2026 (prior balance ~$12.8B). Confirm vs. next 10-Q.
B10: Net cash ($B) | C10: =C8-C9 -> 15.2
B11: FY2026A Revenue ($B) — forecast anchor | C11: 215.9 | H11: Source: NVIDIA Q4/FY2026 earnings release, 2/2026.
B13: WACC Build (Base Case Derivation — see WACC tab for full walkthrough)
B14: Risk-free rate (10-yr UST) | C14: 0.046 | H14: Source: 10-yr Treasury yield, ~8/6/2026.
B15: Equity risk premium (implied, US) | C15: 0.045 | H15: Source: Damodaran implied ERP update, July 2026 (4.45%, rounded).
B16: Beta (5Y, vs. S&P 500) | C16: 2.2 | H16: Source: avg. of Google Finance / stockanalysis.com reported beta, ~2.2-2.3 range.
B17: Cost of equity (CAPM) | C17: =C14+C16*C15 -> 0.145
B18: Pre-tax cost of debt | C18: 0.0525 | H18: Source: NVDA 30Y bond priced at UST+65bps, June 2026 issuance (Aa1/AA- rated).
B19: Marginal tax rate (for WACC) | C19: 0.21 | H19: U.S. federal statutory rate — used for the debt tax shield, not the effective P&L tax rate.
B20: After-tax cost of debt | C20: =C18*(1-C19) -> 0.041475
B21: Market value of equity ($B) | C21: =C6*C7 -> 5207.3
B22: Market value of debt ($B) | C22: =C9 -> 38
B23: Weight of equity | C23: =C21/(C21+C22) -> 0.99275542
B24: Weight of debt | C24: =C22/(C21+C22) -> 0.0072445809
B25: WACC (Base, derived) | C25: =C23*C17+C24*C20 -> 0.14425
B27: Scenario Toggle — Discount Rate & Terminal Value Levers
C28: Bear | D28: Base | E28: Bull | F28: Active
B29: WACC | C29: 0.165 | D29: =C25 -> 0.14425 | E29: 0.13 | F29: =IF($C$3="Bear",C29,IF($C$3="Base",D29,E29)) -> 0.14425
B30: Terminal growth rate (g) | C30: 0.025 | D30: 0.035 | E30: 0.045 | F30: =IF($C$3="Bear",C30,IF($C$3="Base",D30,E30)) -> 0.035
B31: Exit EV/EBITDA multiple (FY31) | C31: 14 | D31: 18 | E31: 24 | F31: =IF($C$3="Bear",C31,IF($C$3="Base",D31,E31)) -> 18
B33: Revenue Growth % by Year
C34: Bear | D34: Base | E34: Bull | F34: Active
B35: FY2027E | C35: 0.82 | D35: 0.82 | E35: 0.82 | F35: =IF($C$3="Bear",C35,IF($C$3="Base",D35,E35)) -> 0.82
B36: FY2028E | C36: 0.14 | D36: 0.18 | E36: 0.22 | F36: =IF($C$3="Bear",C36,IF($C$3="Base",D36,E36)) -> 0.18
B37: FY2029E | C37: 0.12 | D37: 0.16 | E37: 0.2 | F37: =IF($C$3="Bear",C37,IF($C$3="Base",D37,E37)) -> 0.16
B38: FY2030E | C38: 0.1 | D38: 0.14 | E38: 0.18 | F38: =IF($C$3="Bear",C38,IF($C$3="Base",D38,E38)) -> 0.14
B39: FY2031E | C39: 0.08 | D39: 0.12 | E39: 0.16 | F39: =IF($C$3="Bear",C39,IF($C$3="Base",D39,E39)) -> 0.12
B41: Gross Margin % by Year
C42: Bear | D42: Base | E42: Bull | F42: Active
B43: FY2027E | C43: 0.749 | D43: 0.75 | E43: 0.75 | F43: =IF($C$3="Bear",C43,IF($C$3="Base",D43,E43)) -> 0.75
B44: FY2028E | C44: 0.72 | D44: 0.74 | E44: 0.755 | F44: =IF($C$3="Bear",C44,IF($C$3="Base",D44,E44)) -> 0.74
B45: FY2029E | C45: 0.7 | D45: 0.73 | E45: 0.755 | F45: =IF($C$3="Bear",C45,IF($C$3="Base",D45,E45)) -> 0.73
B46: FY2030E | C46: 0.69 | D46: 0.725 | E46: 0.755 | F46: =IF($C$3="Bear",C46,IF($C$3="Base",D46,E46)) -> 0.725
...

Sheet Historical
B1: NVIDIA — FIVE-YEAR HISTORICAL INCOME STATEMENT (FY2022–FY2026)
B2: $ in billions except per-share data. Fiscal year ends late January.
C4: FY2022A | D4: FY2023A | E4: FY2024A | F4: FY2025A | G4: FY2026A
B6: Revenue ($B) | C6: 26.91 | D6: 26.97 | E6: 60.92 | F6: 130.5 | G6: 215.9 | I6: Source: NVIDIA 10-K filings / quarterly earnings releases, FY2022-FY2026.
B7: Revenue growth % YoY | C7: n/a | D7: =D6/C6-1 -> 0.0022296544 | E7: =E6/D6-1 -> 1.2588061 | F7: =F6/E6-1 -> 1.1421536 | G7: =G6/F6-1 -> 0.65440613
B9: Gross margin % | C9: 0.649 | D9: 0.569 | E9: 0.727 | F9: 0.75 | G9: 0.711 | I9: FY22/24/26 per NVIDIA press releases. FY23/25 approximated (marked with * below) — replace with exact 10-K figures for final use.
B10: Gross profit ($B) | C10: =C6*C9 -> 17.46459 | D10: =D6*D9 -> 15.34593 | E10: =E6*E9 -> 44.28884 | F10: =F6*F9 -> 97.875 | G10: =G6*G9 -> 153.5049
B12: Operating income ($B) | C12: 10.04 | D12: 4.224 | E12: 32.97 | F12: 81.453 | G12: 130.39 | I12: Source: NVIDIA Q4 FY2024 earnings release (FY23 operating income, from GAAP reconciliation table) and NVIDIA Q4 FY2026 earnings release (FY25 operating income). All five years now sourced directly, no approximations.
B13: Operating margin % | C13: =C12/C6 -> 0.3730955 | D13: =D12/D6 -> 0.15661846 | E13: =E12/E6 -> 0.54120158 | F13: =F12/F6 -> 0.62416092 | G13: =G12/G6 -> 0.60393701
B15: Net income ($B) | C15: 9.752 | D15: 4.368 | E15: 29.76 | F15: 72.9 | G15: 120.07 | I15: Source: NVIDIA quarterly/annual earnings releases, FY2022-FY2026 (10-K equivalent GAAP figures). All five years now sourced directly, no approximations.
B16: Net margin % | C16: =C15/C6 -> 0.36239316 | D16: =D15/D6 -> 0.16195773 | E16: =E15/E6 -> 0.48850952 | F16: =F15/F6 -> 0.55862069 | G16: =G15/G6 -> 0.5561371
B18: Diluted EPS — as reported ($) | C18: 3.85 | D18: 1.74 | E18: 11.93 | F18: 2.94 | G18: 4.9 | I18: GAAP diluted EPS as originally reported each fiscal year (pre-split for FY22-24).
B19: Diluted EPS — split-adjusted ($) | C19: =C18/10 -> 0.385 | D19: =D18/10 -> 0.174 | E19: =E18/10 -> 1.193 | F19: =F18 -> 2.94 | G19: =G18 -> 4.9 | I19: 10-for-1 stock split effective June 7, 2024 — FY22-FY24 divided by 10 for comparability. FY25/FY26 already post-split.
B21: All five years of Revenue, Operating Income, and Net Income are now sourced directly from NVIDIA's GAAP earnings releases (see source notes above) — no derived approximations remain.

Sheet Forecast
B1: NVIDIA — FIVE-YEAR FORECAST (FY2027E–FY2031E)
B2: $ in billions. All drivers pulled from Inputs!Active column — flips automatically with the scenario toggle.
C4: FY2027E | D4: FY2028E | E4: FY2029E | F4: FY2030E | G4: FY2031E
B5: Revenue growth % YoY | C5: =Inputs!$F$35 -> 0.82 | D5: =Inputs!$F$36 -> 0.18 | E5: =Inputs!$F$37 -> 0.16 | F5: =Inputs!$F$38 -> 0.14 | G5: =Inputs!$F$39 -> 0.12
B6: Revenue | C6: =Inputs!$C$11*(1+C5) -> 392.938 | D6: =C6*(1+D5) -> 463.66684 | E6: =D6*(1+E5) -> 537.85353 | F6: =E6*(1+F5) -> 613.15303 | G6: =F6*(1+G5) -> 686.73139
B7: COGS | C7: =C6*(1-C8) -> 98.2345 | D7: =D6*(1-D8) -> 120.55338 | E7: =E6*(1-E8) -> 145.22045 | F7: =F6*(1-F8) -> 168.61708 | G7: =G6*(1-G8) -> 192.28479
B8: Gross margin % | C8: =Inputs!$F$43 -> 0.75 | D8: =Inputs!$F$44 -> 0.74 | E8: =Inputs!$F$45 -> 0.73 | F8: =Inputs!$F$46 -> 0.725 | G8: =Inputs!$F$47 -> 0.72
B9: Gross profit | C9: =C6-C7 -> 294.7035 | D9: =D6-D7 -> 343.11346 | E9: =E6-E7 -> 392.63308 | F9: =F6-F7 -> 444.53595 | G9: =G6-G7 -> 494.4466
B10: Opex % of revenue | C10: =Inputs!$F$51 -> 0.095 | D10: =Inputs!$F$52 -> 0.09 | E10: =Inputs!$F$53 -> 0.085 | F10: =Inputs!$F$54 -> 0.085 | G10: =Inputs!$F$55 -> 0.085
B11: Operating expenses (R&D + SG&A) | C11: =C6*C10 -> 37.32911 | D11: =D6*D10 -> 41.730016 | E11: =E6*E10 -> 45.71755 | F11: =F6*F10 -> 52.118007 | G11: =G6*G10 -> 58.372168
B12: EBIT | C12: =C9-C11 -> 257.37439 | D12: =D9-D11 -> 301.38345 | E12: =E9-E11 -> 346.91553 | F12: =F9-F11 -> 392.41794 | G12: =G9-G11 -> 436.07443
B13: EBIT margin % | C13: =C12/C6 -> 0.655 | D13: =D12/D6 -> 0.65 | E13: =E12/E6 -> 0.645 | F13: =F12/F6 -> 0.64 | G13: =G12/G6 -> 0.635
B14: EBITDA (EBIT + D&A) | C14: =C12+C18 -> 265.23315 | D14: =D12+D18 -> 310.65678 | E14: =E12+E18 -> 357.6726 | F14: =F12+F18 -> 404.681 | G14: =G12+G18 -> 449.80906
B15: Effective tax rate % | C15: =Inputs!$F$59 -> 0.17 | D15: =Inputs!$F$60 -> 0.18 | E15: =Inputs!$F$61 -> 0.19 | F15: =Inputs!$F$62 -> 0.2 | G15: =Inputs!$F$63 -> 0.21
B16: Cash taxes | C16: =C12*C15 -> 43.753646 | D16: =D12*D15 -> 54.24902 | E16: =E12*E15 -> 65.913951 | F16: =F12*F15 -> 78.483588 | G16: =G12*G15 -> 91.575631
B17: D&A % of revenue | C17: =Inputs!$F$67 -> 0.02 | D17: =Inputs!$F$68 -> 0.02 | E17: =Inputs!$F$69 -> 0.02 | F17: =Inputs!$F$70 -> 0.02 | G17: =Inputs!$F$71 -> 0.02
B18: D&A | C18: =C6*C17 -> 7.85876 | D18: =D6*D17 -> 9.2733368 | E18: =E6*E17 -> 10.757071 | F18: =F6*F17 -> 12.263061 | G18: =G6*G17 -> 13.734628
B19: NOPAT (unlevered net income) | C19: =C12-C16 -> 213.62074 | D19: =D12-D16 -> 247.13443 | E19: =E12-E16 -> 281.00158 | F19: =F12-F16 -> 313.93435 | G19: =G12-G16 -> 344.4988
B21: CapEx % of revenue | C21: =Inputs!$F$75 -> 0.035 | D21: =Inputs!$F$76 -> 0.038 | E21: =Inputs!$F$77 -> 0.04 | F21: =Inputs!$F$78 -> 0.043 | G21: =Inputs!$F$79 -> 0.045
B22: CapEx | C22: =C6*C21 -> 13.75283 | D22: =D6*D21 -> 17.61934 | E22: =E6*E21 -> 21.514141 | F22: =F6*F21 -> 26.36558 | G22: =G6*G21 -> 30.902913
B23: NWC increase % of incremental revenue | C23: =Inputs!$F$83 -> 0.08 | D23: =Inputs!$F$84 -> 0.08 | E23: =Inputs!$F$85 -> 0.06 | F23: =Inputs!$F$86 -> 0.05 | G23: =Inputs!$F$87 -> 0.04
B24: Incremental revenue (YoY $) | C24: =C6-Inputs!$C$11 -> 177.038 | D24: =D6-C6 -> 70.72884 | E24: =E6-D6 -> 74.186694 | F24: =F6-E6 -> 75.299495 | G24: =G6-F6 -> 73.578364
B25: Increase in net working capital | C25: =C24*C23 -> 14.16304 | D25: =D24*D23 -> 5.6583072 | E25: =E24*E23 -> 4.4512017 | F25: =F24*F23 -> 3.7649747 | G25: =G24*G23 -> 2.9431345
B27: Unlevered Free Cash Flow | C27: =C19+C18-C22-C25 -> 193.56363 | D27: =D19+D18-D22-D25 -> 233.13012 | E27: =E19+E18-E22-E25 -> 265.79331 | F27: =F19+F18-F22-F25 -> 296.06686 | G27: =G19+G18-G22-G25 -> 324.38738 | I27: Formula: NOPAT + D&A - CapEx - Increase in NWC. This is the row the DCF tab discounts.
B29: FCF margin % (UFCF / Revenue) | C29: =C27/C6 -> 0.49260604 | D29: =D27/D6 -> 0.50279661 | E29: =E27/E6 -> 0.49417414 | F29: =F27/F6 -> 0.48285965 | G29: =G27/G6 -> 0.47236429

Sheet WACC
B1: NVIDIA — WACC DERIVATION (BASE CASE)
B3: Cost of Equity — CAPM
B4: Risk-free rate (Rf) | C4: =Inputs!C14 -> 0.046 | E4: 10-yr UST yield, ~8/6/2026.
B5: Equity risk premium (ERP) | C5: =Inputs!C15 -> 0.045 | E5: Damodaran implied ERP, July 2026.
B6: Beta | C6: =Inputs!C16 -> 2.2 | E6: 5Y beta vs. S&P 500.
B7: Cost of Equity = Rf + Beta x ERP | C7: =C4+C6*C5 -> 0.145
B9: Cost of Debt
B10: Pre-tax cost of debt | C10: =Inputs!C18 -> 0.0525 | E10: NVDA 30Y bond priced at UST+65bps, June 2026 ($25B issuance, Aa1/AA- rated).
B11: Marginal tax rate | C11: =Inputs!C19 -> 0.21
B12: After-tax cost of debt = Kd x (1 - T) | C12: =C10*(1-C11) -> 0.041475
B14: Capital Structure (Market Value Weights)
B15: Market value of equity ($B) | C15: =Inputs!C21 -> 5207.3
B16: Market value of debt ($B) | C16: =Inputs!C22 -> 38
B17: Weight of equity | C17: =C15/(C15+C16) -> 0.99275542
B18: Weight of debt | C18: =C16/(C15+C16) -> 0.0072445809
B20: WACC
B21: WACC = (We x Ke) + (Wd x Kd(1-T)) | C21: =C17*C7+C18*C12 -> 0.14425 | E21: This is the value that flows into Inputs!D29 (Base column of the scenario toggle).

Sheet DCF
B1: NVIDIA — DCF: DISCOUNTED CASH FLOW & INTRINSIC VALUE
B2: $ in billions except per-share data. All figures reflect the Active scenario selected on the Inputs tab.
C4: FY2027E | D4: FY2028E | E4: FY2029E | F4: FY2030E | G4: FY2031E
B5: Forecast year # | C5: 1 | D5: 2 | E5: 3 | F5: 4 | G5: 5
B6: Unlevered Free Cash Flow | C6: =Forecast!C27 -> 193.56363 | D6: =Forecast!D27 -> 233.13012 | E6: =Forecast!E27 -> 265.79331 | F6: =Forecast!F27 -> 296.06686 | G6: =Forecast!G27 -> 324.38738
B7: Discount factor @ Active WACC | C7: =1/(1+Inputs!$F$29)^C5 -> 0.87393489 | D7: =1/(1+Inputs!$F$29)^D5 -> 0.76376219 | E7: =1/(1+Inputs!$F$29)^E5 -> 0.66747842 | F7: =1/(1+Inputs!$F$29)^F5 -> 0.58333268 | G7: =1/(1+Inputs!$F$29)^G5 -> 0.50979478
B8: PV of Free Cash Flow | C8: =C6*C7 -> 169.16201 | D8: =D6*D7 -> 178.05597 | E8: =E6*E7 -> 177.4113 | F8: =F6*F7 -> 172.70547 | G8: =G6*G7 -> 165.371
B10: Sum of PV of FCF (Years 1-5) | C10: =SUM(C8:G8) -> 862.70575
B12: Terminal Value — Method 1: Perpetuity Growth
B13: Terminal growth rate (g) | C13: =Inputs!$F$30 -> 0.035
B14: Terminal Value = FCFyr5 x (1+g) / (WACC-g) | C14: =G6*(1+C13)/(Inputs!$F$29-C13) -> 3073.1435
B15: PV of Terminal Value | C15: =C14*G7 -> 1566.6725
B16: Enterprise Value (Perpetuity) | C16: =C10+C15 -> 2429.3783
B17: (+) Net cash | C17: =Inputs!$C$10 -> 15.2
B18: Equity Value (Perpetuity) | C18: =C16+C17 -> 2444.5783
B19: Diluted shares outstanding (B) | C19: =Inputs!$C$7 -> 24.22
B20: Intrinsic Value per Share — Perpetuity Method | C20: =C18/C19 -> 100.93222
B22: Terminal Value — Method 2: Exit Multiple
B23: Exit EV/EBITDA multiple | C23: =Inputs!$F$31 -> 18
B24: FY2031E EBITDA | C24: =Forecast!G14 -> 449.80906
B25: Terminal Value = EBITDAyr5 x Multiple | C25: =C24*C23 -> 8096.5631
B26: PV of Terminal Value | C26: =C25*G7 -> 4127.5856
B27: Enterprise Value (Exit Multiple) | C27: =C10+C26 -> 4990.2914
B28: (+) Net cash | C28: =Inputs!$C$10 -> 15.2
B29: Equity Value (Exit Multiple) | C29: =C27+C28 -> 5005.4914
B30: Diluted shares outstanding (B) | C30: =Inputs!$C$7 -> 24.22
B31: Intrinsic Value per Share — Exit Multiple Method | C31: =C29/C30 -> 206.66769
B33: Bridge to Current Price
B34: Current share price | C34: =Inputs!$C$6 -> 215
B35: Implied upside / (downside) — Perpetuity | C35: =C20/C34-1 -> -0.53054783
B36: Implied upside / (downside) — Exit Multiple | C36: =C31/C34-1 -> -0.038754946

Sheet Sensitivity
B1: NVIDIA — SENSITIVITY ANALYSIS
B2: Tables flex WACC / terminal growth / exit multiple around the Forecast tab's currently Active scenario FCF & EBITDA path.
B4: Discount Factor Helper (per WACC scenario row)
B5: WACC \ Year | C5: 1 | D5: 2 | E5: 3 | F5: 4 | G5: 5 | H5: Sum PV of FCF
B6: 0.125 | C6: =1/(1+$B6)^C$5 -> 0.88888889 | D6: =1/(1+$B6)^D$5 -> 0.79012346 | E6: =1/(1+$B6)^E$5 -> 0.70233196 | F6: =1/(1+$B6)^F$5 -> 0.62429508 | G6: =1/(1+$B6)^G$5 -> 0.55492896 | H6: =SUMPRODUCT(C6:G6,Forecast!$C$27:$G$27) -> 907.7783
B7: 0.135 | C7: =1/(1+$B7)^C$5 -> 0.88105727 | D7: =1/(1+$B7)^D$5 -> 0.77626191 | E7: =1/(1+$B7)^E$5 -> 0.6839312 | F7: =1/(1+$B7)^F$5 -> 0.60258255 | G7: =1/(1+$B7)^G$5 -> 0.53090974 | H7: =SUMPRODUCT(C7:G7,Forecast!$C$27:$G$27) -> 883.92015
B8: 0.144 | C8: =1/(1+$B8)^C$5 -> 0.87412587 | D8: =1/(1+$B8)^D$5 -> 0.76409604 | E8: =1/(1+$B8)^E$5 -> 0.66791612 | F8: =1/(1+$B8)^F$5 -> 0.58384276 | G8: =1/(1+$B8)^G$5 -> 0.51035207 | H8: =SUMPRODUCT(C8:G8,Forecast!$C$27:$G$27) -> 863.26868
B9: 0.155 | C9: =1/(1+$B9)^C$5 -> 0.86580087 | D9: =1/(1+$B9)^D$5 -> 0.74961114 | E9: =1/(1+$B9)^E$5 -> 0.64901397 | F9: =1/(1+$B9)^F$5 -> 0.56191686 | G9: =1/(1+$B9)^G$5 -> 0.4865081 | H9: =SUMPRODUCT(C9:G9,Forecast!$C$27:$G$27) -> 839.03011
B10: 0.165 | C10: =1/(1+$B10)^C$5 -> 0.8583691 | D10: =1/(1+$B10)^D$5 -> 0.73679751 | E10: =1/(1+$B10)^E$5 -> 0.63244421 | F10: =1/(1+$B10)^F$5 -> 0.54287057 | G10: =1/(1+$B10)^G$5 -> 0.46598332 | H10: =SUMPRODUCT(C10:G10,Forecast!$C$27:$G$27) -> 817.90326
B13: Table 1: WACC vs. Terminal Growth Rate — Implied Share Price (Perpetuity Method)
B14: WACC \ g | C14: 0.025 | D14: 0.03 | E14: 0.035 | F14: 0.04 | G14: 0.045
B15: =B6 -> 0.125 | C15: =($H6+(Forecast!$G$27*(1+C$14)/($B15-C$14))*$G6+Inputs!$C$10)/Inputs!$C$7 -> 114.28988 | D15: =($H6+(Forecast!$G$27*(1+D$14)/($B15-D$14))*$G6+Inputs!$C$10)/Inputs!$C$7 -> 118.69062 | E15: =($H6+(Forecast!$G$27*(1+E$14)/($B15-E$14))*$G6+Inputs!$C$10)/Inputs!$C$7 -> 123.58034 | F15: =($H6+(Forecast!$G$27*(1+F$14)/($B15-F$14))*$G6+Inputs!$C$10)/Inputs!$C$7 -> 129.04531 | G15: =($H6+(Forecast!$G$27*(1+G$14)/($B15-G$14))*$G6+Inputs!$C$10)/Inputs!$C$7 -> 135.19341
B16: =B7 -> 0.135 | C16: =($H7+(Forecast!$G$27*(1+C$14)/($B16-C$14))*$G7+Inputs!$C$10)/Inputs!$C$7 -> 103.38156 | D16: =($H7+(Forecast!$G$27*(1+D$14)/($B16-D$14))*$G7+Inputs!$C$10)/Inputs!$C$7 -> 106.87533 | E16: =($H7+(Forecast!$G$27*(1+E$14)/($B16-E$14))*$G7+Inputs!$C$10)/Inputs!$C$7 -> 110.71848 | F16: =($H7+(Forecast!$G$27*(1+F$14)/($B16-F$14))*$G7+Inputs!$C$10)/Inputs!$C$7 -> 114.96617 | G16: =($H7+(Forecast!$G$27*(1+G$14)/($B16-G$14))*$G7+Inputs!$C$10)/Inputs!$C$7 -> 119.68582
B17: =B8 -> 0.144 | C17: =($H8+(Forecast!$G$27*(1+C$14)/($B17-C$14))*$G8+Inputs!$C$10)/Inputs!$C$7 -> 95.146153 | D17: =($H8+(Forecast!$G$27*(1+D$14)/($B17-D$14))*$G8+Inputs!$C$10)/Inputs!$C$7 -> 98.028219 | E17: =($H8+(Forecast!$G$27*(1+E$14)/($B17-E$14))*$G8+Inputs!$C$10)/Inputs!$C$7 -> 101.17469 | F17: =($H8+(Forecast!$G$27*(1+F$14)/($B17-F$14))*$G8+Inputs!$C$10)/Inputs!$C$7 -> 104.62372 | G17: =($H8+(Forecast!$G$27*(1+G$14)/($B17-G$14))*$G8+Inputs!$C$10)/Inputs!$C$7 -> 108.42112
B18: =B9 -> 0.155 | C18: =($H9+(Forecast!$G$27*(1+C$14)/($B18-C$14))*$G9+Inputs!$C$10)/Inputs!$C$7 -> 86.645631 | D18: =($H9+(Forecast!$G$27*(1+D$14)/($B18-D$14))*$G9+Inputs!$C$10)/Inputs!$C$7 -> 88.961311 | E18: =($H9+(Forecast!$G$27*(1+E$14)/($B18-E$14))*$G9+Inputs!$C$10)/Inputs!$C$7 -> 91.469964 | F18: =($H9+(Forecast!$G$27*(1+F$14)/($B18-F$14))*$G9+Inputs!$C$10)/Inputs!$C$7 -> 94.196761 | G18: =($H9+(Forecast!$G$27*(1+G$14)/($B18-G$14))*$G9+Inputs!$C$10)/Inputs!$C$7 -> 97.171448
B19: =B10 -> 0.165 | C19: =($H10+(Forecast!$G$27*(1+C$14)/($B19-C$14))*$G10+Inputs!$C$10)/Inputs!$C$7 -> 80.090995 | D19: =($H10+(Forecast!$G$27*(1+D$14)/($B19-D$14))*$G10+Inputs!$C$10)/Inputs!$C$7 -> 82.014504 | E19: =($H10+(Forecast!$G$27*(1+E$14)/($B19-E$14))*$G10+Inputs!$C$10)/Inputs!$C$7 -> 84.085976 | F19: =($H10+(Forecast!$G$27*(1+F$14)/($B19-F$14))*$G10+Inputs!$C$10)/Inputs!$C$7 -> 86.323165 | G19: =($H10+(Forecast!$G$27*(1+G$14)/($B19-G$14))*$G10+Inputs!$C$10)/Inputs!$C$7 -> 88.746787
B21: Table 2: WACC vs. Exit EV/EBITDA Multiple — Implied Share Price (Exit Multiple Method)
B22: WACC \ Multiple | C22: 14 | D22: 16 | E22: 18 | F22: 20 | G22: 22
B23: =B6 -> 0.125 | C23: =($H6+(Forecast!$G$14*C$22)*$G6+Inputs!$C$10)/Inputs!$C$7 -> 182.39254 | D23: =($H6+(Forecast!$G$14*D$22)*$G6+Inputs!$C$10)/Inputs!$C$7 -> 203.0046 | E23: =($H6+(Forecast!$G$14*E$22)*$G6+Inputs!$C$10)/Inputs!$C$7 -> 223.61667 | F23: =($H6+(Forecast!$G$14*F$22)*$G6+Inputs!$C$10)/Inputs!$C$7 -> 244.22873 | G23: =($H6+(Forecast!$G$14*G$22)*$G6+Inputs!$C$10)/Inputs!$C$7 -> 264.84079
B24: =B7 -> 0.135 | C24: =($H7+(Forecast!$G$14*C$22)*$G7+Inputs!$C$10)/Inputs!$C$7 -> 175.16236 | D24: =($H7+(Forecast!$G$14*D$22)*$G7+Inputs!$C$10)/Inputs!$C$7 -> 194.88226 | E24: =($H7+(Forecast!$G$14*E$22)*$G7+Inputs!$C$10)/Inputs!$C$7 -> 214.60216 | F24: =($H7+(Forecast!$G$14*F$22)*$G7+Inputs!$C$10)/Inputs!$C$7 -> 234.32206 | G24: =($H7+(Forecast!$G$14*G$22)*$G7+Inputs!$C$10)/Inputs!$C$7 -> 254.04197
B25: =B8 -> 0.144 | C25: =($H8+(Forecast!$G$14*C$22)*$G8+Inputs!$C$10)/Inputs!$C$7 -> 168.96459 | D25: =($H8+(Forecast!$G$14*D$22)*$G8+Inputs!$C$10)/Inputs!$C$7 -> 187.92091 | E25: =($H8+(Forecast!$G$14*E$22)*$G8+Inputs!$C$10)/Inputs!$C$7 -> 206.87723 | F25: =($H8+(Forecast!$G$14*F$22)*$G8+Inputs!$C$10)/Inputs!$C$7 -> 225.83354 | G25: =($H8+(Forecast!$G$14*G$22)*$G8+Inputs!$C$10)/Inputs!$C$7 -> 244.78986
B26: =B9 -> 0.155 | C26: =($H9+(Forecast!$G$14*C$22)*$G9+Inputs!$C$10)/Inputs!$C$7 -> 161.76427 | D26: =($H9+(Forecast!$G$14*D$22)*$G9+Inputs!$C$10)/Inputs!$C$7 -> 179.83494 | E26: =($H9+(Forecast!$G$14*E$22)*$G9+Inputs!$C$10)/Inputs!$C$7 -> 197.9056 | F26: =($H9+(Forecast!$G$14*F$22)*$G9+Inputs!$C$10)/Inputs!$C$7 -> 215.97627 | G26: =($H9+(Forecast!$G$14*G$22)*$G9+Inputs!$C$10)/Inputs!$C$7 -> 234.04693
B27: =B10 -> 0.165 | C27: =($H10+(Forecast!$G$14*C$22)*$G10+Inputs!$C$10)/Inputs!$C$7 -> 155.55543 | D27: =($H10+(Forecast!$G$14*D$22)*$G10+Inputs!$C$10)/Inputs!$C$7 -> 172.86373 | E27: =($H10+(Forecast!$G$14*E$22)*$G10+Inputs!$C$10)/Inputs!$C$7 -> 190.17203 | F27: =($H10+(Forecast!$G$14*F$22)*$G10+Inputs!$C$10)/Inputs!$C$7 -> 207.48033 | G27: =($H10+(Forecast!$G$14*G$22)*$G10+Inputs!$C$10)/Inputs!$C$7 -> 224.78863
B29: Yellow highlight = approx. current base-case combination (WACC 14.4%, g 3.5% / multiple 18.0x).

Sheet Dashboard
B2: NVIDIA (NVDA) — VALUATION DASHBOARD
B5: Active scenario: | C5: =Inputs!C3 -> Base | F5: Change the dropdown on the Inputs tab (cell C3) to flip Bear / Base / Bull — this entire dashboard updates.
B7: Key Outputs
B8: Current share price | C8: =Inputs!C6 -> 215
B9: WACC (active) | C9: =Inputs!F29 -> 0.14425
B10: Terminal growth rate (active) | C10: =Inputs!F30 -> 0.035
B11: Exit EV/EBITDA multiple (active) | C11: =Inputs!F31 -> 18
B12: Intrinsic value — Perpetuity method | C12: =DCF!C20 -> 100.93222
B13: Upside/(downside) — Perpetuity | C13: =DCF!C35 -> -0.53054783
B14: Intrinsic value — Exit Multiple method | C14: =DCF!C31 -> 206.66769
B15: Upside/(downside) — Exit Multiple | C15: =DCF!C36 -> -0.038754946
B16: FY2027E Revenue | C16: =Forecast!C6 -> 392.938
B17: FY2031E Revenue | C17: =Forecast!G6 -> 686.73139
B18: FY2031E Unlevered FCF | C18: =Forecast!G27 -> 324.38738
B19: 5-yr Revenue CAGR (FY26A-FY31E) | C19: =(Forecast!G6/Inputs!C11)^(1/5)-1 -> 0.26039552
B21: Interpretation Notes
B22: The two terminal value methods typically diverge meaningfully (see Sensitivity tab) because the Perpetuity Growth method forces a single permanent growth rate, while the Exit Multiple method lets the market's own forward view of durability and moat strength flow through the multiple. Treat the gap between the two as the valuation range, not an error to reconcile away.

Sheet Charts
B1: NVIDIA — CHARTS
B3: Fiscal Year | C3: FY22A | D3: FY23A | E3: FY24A | F3: FY25A | G3: FY26A | H3: FY27E | I3: FY28E | J3: FY29E | K3: FY30E | L3: FY31E
B4: Revenue ($B) | C4: =Historical!C6 -> 26.91 | D4: =Historical!D6 -> 26.97 | E4: =Historical!E6 -> 60.92 | F4: =Historical!F6 -> 130.5 | G4: =Historical!G6 -> 215.9 | H4: =Forecast!C6 -> 392.938 | I4: =Forecast!D6 -> 463.66684 | J4: =Forecast!E6 -> 537.85353 | K4: =Forecast!F6 -> 613.15303 | L4: =Forecast!G6 -> 686.73139
B5: Unlevered FCF ($B) | H5: =Forecast!C27 -> 193.56363 | I5: =Forecast!D27 -> 233.13012 | J5: =Forecast!E27 -> 265.79331 | K5: =Forecast!F27 -> 296.06686 | L5: =Forecast!G27 -> 324.38738
